<?xml version="1.0" encoding="UTF-8"?>
<testsuite name="销售服务系统-登录接口测试场景点"
           tests="10"
           failures="9"
           errors="0"
           skipped="0"
           time="30.816">
  <properties />
            <testcase name="Case4" time="3.051" classname="TestCase.LoginTest">
                <failure type="java.lang.AssertionError"
                  message="roleId =&gt;Expected 【SA1】 but found 【SA】"
              >
<![CDATA[java.lang.AssertionError: roleId =>Expected 【SA1】 but found 【SA】
  org.testng.Assert.fail(Assert.java:94)
  com.sales.webapi.handler.LoginApi_Handler.checkEquals(LoginApi_Handler.java:539)
  com.sales.webapi.handler.LoginApi_Handler.resultCheck(LoginApi_Handler.java:473)
  TestCase.LoginTest.Case4(LoginTest.java:38)
  sun.reflect.NativeMethodAccessorImpl.invoke0(Native Method)
  sun.reflect.NativeMethodAccessorImpl.invoke(Unknown Source)
  sun.reflect.DelegatingMethodAccessorImpl.invoke(Unknown Source)
  java.lang.reflect.Method.invoke(Unknown Source)
  org.testng.internal.MethodInvocationHelper.invokeMethod(MethodInvocationHelper.java:86)
  org.testng.internal.InvokeMethodRunnable.runOne(InvokeMethodRunnable.java:54)
  org.testng.internal.InvokeMethodRunnable.run(InvokeMethodRunnable.java:44)
  java.util.concurrent.Executors$RunnableAdapter.call(Unknown Source)
  java.util.concurrent.FutureTask.run(Unknown Source)
  java.util.concurrent.ThreadPoolExecutor.runWorker(Unknown Source)
  java.util.concurrent.ThreadPoolExecutor$Worker.run(Unknown Source)
  java.lang.Thread.run(Unknown Source)
]]>
      </failure>

          </testcase>
            <testcase name="Case9" time="2.985" classname="TestCase.LoginTest">
                <failure type="java.lang.AssertionError"
                  message="photoName =&gt;Expected 【http://10.10.11.136/group1/M11/55/AE/CgsLxVk2Hn6AKeL9AANFJEeS22Y23.Jpeg1】 but found 【http://10.10.11.136/group1/M11/55/AE/CgsLxVk2Hn6AKeL9AANFJEeS22Y23.Jpeg】"
              >
<![CDATA[java.lang.AssertionError: photoName =>Expected 【http://10.10.11.136/group1/M11/55/AE/CgsLxVk2Hn6AKeL9AANFJEeS22Y23.Jpeg1】 but found 【http://10.10.11.136/group1/M11/55/AE/CgsLxVk2Hn6AKeL9AANFJEeS22Y23.Jpeg】
  org.testng.Assert.fail(Assert.java:94)
  com.sales.webapi.handler.LoginApi_Handler.checkEquals(LoginApi_Handler.java:539)
  com.sales.webapi.handler.LoginApi_Handler.resultCheck(LoginApi_Handler.java:478)
  TestCase.LoginTest.Case9(LoginTest.java:68)
  sun.reflect.NativeMethodAccessorImpl.invoke0(Native Method)
  sun.reflect.NativeMethodAccessorImpl.invoke(Unknown Source)
  sun.reflect.DelegatingMethodAccessorImpl.invoke(Unknown Source)
  java.lang.reflect.Method.invoke(Unknown Source)
  org.testng.internal.MethodInvocationHelper.invokeMethod(MethodInvocationHelper.java:86)
  org.testng.internal.InvokeMethodRunnable.runOne(InvokeMethodRunnable.java:54)
  org.testng.internal.InvokeMethodRunnable.run(InvokeMethodRunnable.java:44)
  java.util.concurrent.Executors$RunnableAdapter.call(Unknown Source)
  java.util.concurrent.FutureTask.run(Unknown Source)
  java.util.concurrent.ThreadPoolExecutor.runWorker(Unknown Source)
  java.util.concurrent.ThreadPoolExecutor$Worker.run(Unknown Source)
  java.lang.Thread.run(Unknown Source)
]]>
      </failure>

          </testcase>
            <testcase name="Case7" time="2.983" classname="TestCase.LoginTest">
                <failure type="java.lang.AssertionError"
                  message="userName =&gt;Expected 【King1】 but found 【King】"
              >
<![CDATA[java.lang.AssertionError: userName =>Expected 【King1】 but found 【King】
  org.testng.Assert.fail(Assert.java:94)
  com.sales.webapi.handler.LoginApi_Handler.checkEquals(LoginApi_Handler.java:539)
  com.sales.webapi.handler.LoginApi_Handler.resultCheck(LoginApi_Handler.java:476)
  TestCase.LoginTest.Case7(LoginTest.java:56)
  sun.reflect.NativeMethodAccessorImpl.invoke0(Native Method)
  sun.reflect.NativeMethodAccessorImpl.invoke(Unknown Source)
  sun.reflect.DelegatingMethodAccessorImpl.invoke(Unknown Source)
  java.lang.reflect.Method.invoke(Unknown Source)
  org.testng.internal.MethodInvocationHelper.invokeMethod(MethodInvocationHelper.java:86)
  org.testng.internal.InvokeMethodRunnable.runOne(InvokeMethodRunnable.java:54)
  org.testng.internal.InvokeMethodRunnable.run(InvokeMethodRunnable.java:44)
  java.util.concurrent.Executors$RunnableAdapter.call(Unknown Source)
  java.util.concurrent.FutureTask.run(Unknown Source)
  java.util.concurrent.ThreadPoolExecutor.runWorker(Unknown Source)
  java.util.concurrent.ThreadPoolExecutor$Worker.run(Unknown Source)
  java.lang.Thread.run(Unknown Source)
]]>
      </failure>

          </testcase>
            <testcase name="Case2" time="3.067" classname="TestCase.LoginTest">
                <failure type="java.lang.AssertionError"
                  message="$id =&gt;Expected 【21】 but found 【2】"
              >
<![CDATA[java.lang.AssertionError: $id =>Expected 【21】 but found 【2】
  org.testng.Assert.fail(Assert.java:94)
  com.sales.webapi.handler.LoginApi_Handler.checkEquals(LoginApi_Handler.java:539)
  com.sales.webapi.handler.LoginApi_Handler.resultCheck(LoginApi_Handler.java:471)
  TestCase.LoginTest.Case2(LoginTest.java:26)
  sun.reflect.NativeMethodAccessorImpl.invoke0(Native Method)
  sun.reflect.NativeMethodAccessorImpl.invoke(Unknown Source)
  sun.reflect.DelegatingMethodAccessorImpl.invoke(Unknown Source)
  java.lang.reflect.Method.invoke(Unknown Source)
  org.testng.internal.MethodInvocationHelper.invokeMethod(MethodInvocationHelper.java:86)
  org.testng.internal.InvokeMethodRunnable.runOne(InvokeMethodRunnable.java:54)
  org.testng.internal.InvokeMethodRunnable.run(InvokeMethodRunnable.java:44)
  java.util.concurrent.Executors$RunnableAdapter.call(Unknown Source)
  java.util.concurrent.FutureTask.run(Unknown Source)
  java.util.concurrent.ThreadPoolExecutor.runWorker(Unknown Source)
  java.util.concurrent.ThreadPoolExecutor$Worker.run(Unknown Source)
  java.lang.Thread.run(Unknown Source)
]]>
      </failure>

          </testcase>
            <testcase name="Case6" time="3.130" classname="TestCase.LoginTest">
                <failure type="java.lang.AssertionError"
                  message="salesId =&gt;Expected 【666667】 but found 【666666】"
              >
<![CDATA[java.lang.AssertionError: salesId =>Expected 【666667】 but found 【666666】
  org.testng.Assert.fail(Assert.java:94)
  com.sales.webapi.handler.LoginApi_Handler.checkEquals(LoginApi_Handler.java:539)
  com.sales.webapi.handler.LoginApi_Handler.resultCheck(LoginApi_Handler.java:475)
  TestCase.LoginTest.Case6(LoginTest.java:50)
  sun.reflect.NativeMethodAccessorImpl.invoke0(Native Method)
  sun.reflect.NativeMethodAccessorImpl.invoke(Unknown Source)
  sun.reflect.DelegatingMethodAccessorImpl.invoke(Unknown Source)
  java.lang.reflect.Method.invoke(Unknown Source)
  org.testng.internal.MethodInvocationHelper.invokeMethod(MethodInvocationHelper.java:86)
  org.testng.internal.InvokeMethodRunnable.runOne(InvokeMethodRunnable.java:54)
  org.testng.internal.InvokeMethodRunnable.run(InvokeMethodRunnable.java:44)
  java.util.concurrent.Executors$RunnableAdapter.call(Unknown Source)
  java.util.concurrent.FutureTask.run(Unknown Source)
  java.util.concurrent.ThreadPoolExecutor.runWorker(Unknown Source)
  java.util.concurrent.ThreadPoolExecutor$Worker.run(Unknown Source)
  java.lang.Thread.run(Unknown Source)
]]>
      </failure>

          </testcase>
            <testcase name="Case5" time="3.004" classname="TestCase.LoginTest">
                <failure type="java.lang.AssertionError"
                  message="roleName =&gt;Expected 【销售代表1】 but found 【销售代表】"
              >
<![CDATA[java.lang.AssertionError: roleName =>Expected 【销售代表1】 but found 【销售代表】
  org.testng.Assert.fail(Assert.java:94)
  com.sales.webapi.handler.LoginApi_Handler.checkEquals(LoginApi_Handler.java:539)
  com.sales.webapi.handler.LoginApi_Handler.resultCheck(LoginApi_Handler.java:474)
  TestCase.LoginTest.Case5(LoginTest.java:44)
  sun.reflect.NativeMethodAccessorImpl.invoke0(Native Method)
  sun.reflect.NativeMethodAccessorImpl.invoke(Unknown Source)
  sun.reflect.DelegatingMethodAccessorImpl.invoke(Unknown Source)
  java.lang.reflect.Method.invoke(Unknown Source)
  org.testng.internal.MethodInvocationHelper.invokeMethod(MethodInvocationHelper.java:86)
  org.testng.internal.InvokeMethodRunnable.runOne(InvokeMethodRunnable.java:54)
  org.testng.internal.InvokeMethodRunnable.run(InvokeMethodRunnable.java:44)
  java.util.concurrent.Executors$RunnableAdapter.call(Unknown Source)
  java.util.concurrent.FutureTask.run(Unknown Source)
  java.util.concurrent.ThreadPoolExecutor.runWorker(Unknown Source)
  java.util.concurrent.ThreadPoolExecutor$Worker.run(Unknown Source)
  java.lang.Thread.run(Unknown Source)
]]>
      </failure>

          </testcase>
            <testcase name="Case_10" time="3.005" classname="TestCase.LoginTest">
                <failure type="java.lang.AssertionError"
                  message="$id =&gt;Expected 【21】 but found 【2】"
              >
<![CDATA[java.lang.AssertionError: $id =>Expected 【21】 but found 【2】
  org.testng.Assert.fail(Assert.java:94)
  com.sales.webapi.handler.LoginApi_Handler.checkEquals(LoginApi_Handler.java:539)
  com.sales.webapi.handler.LoginApi_Handler.resultCheck(LoginApi_Handler.java:471)
  TestCase.LoginTest.Case_10(LoginTest.java:74)
  sun.reflect.NativeMethodAccessorImpl.invoke0(Native Method)
  sun.reflect.NativeMethodAccessorImpl.invoke(Unknown Source)
  sun.reflect.DelegatingMethodAccessorImpl.invoke(Unknown Source)
  java.lang.reflect.Method.invoke(Unknown Source)
  org.testng.internal.MethodInvocationHelper.invokeMethod(MethodInvocationHelper.java:86)
  org.testng.internal.InvokeMethodRunnable.runOne(InvokeMethodRunnable.java:54)
  org.testng.internal.InvokeMethodRunnable.run(InvokeMethodRunnable.java:44)
  java.util.concurrent.Executors$RunnableAdapter.call(Unknown Source)
  java.util.concurrent.FutureTask.run(Unknown Source)
  java.util.concurrent.ThreadPoolExecutor.runWorker(Unknown Source)
  java.util.concurrent.ThreadPoolExecutor$Worker.run(Unknown Source)
  java.lang.Thread.run(Unknown Source)
]]>
      </failure>

          </testcase>
            <testcase name="Case8" time="3.139" classname="TestCase.LoginTest">
                <failure type="java.lang.AssertionError"
                  message="identification =&gt;Expected 【string1】 but found 【string】"
              >
<![CDATA[java.lang.AssertionError: identification =>Expected 【string1】 but found 【string】
  org.testng.Assert.fail(Assert.java:94)
  com.sales.webapi.handler.LoginApi_Handler.checkEquals(LoginApi_Handler.java:539)
  com.sales.webapi.handler.LoginApi_Handler.resultCheck(LoginApi_Handler.java:477)
  TestCase.LoginTest.Case8(LoginTest.java:62)
  sun.reflect.NativeMethodAccessorImpl.invoke0(Native Method)
  sun.reflect.NativeMethodAccessorImpl.invoke(Unknown Source)
  sun.reflect.DelegatingMethodAccessorImpl.invoke(Unknown Source)
  java.lang.reflect.Method.invoke(Unknown Source)
  org.testng.internal.MethodInvocationHelper.invokeMethod(MethodInvocationHelper.java:86)
  org.testng.internal.InvokeMethodRunnable.runOne(InvokeMethodRunnable.java:54)
  org.testng.internal.InvokeMethodRunnable.run(InvokeMethodRunnable.java:44)
  java.util.concurrent.Executors$RunnableAdapter.call(Unknown Source)
  java.util.concurrent.FutureTask.run(Unknown Source)
  java.util.concurrent.ThreadPoolExecutor.runWorker(Unknown Source)
  java.util.concurrent.ThreadPoolExecutor$Worker.run(Unknown Source)
  java.lang.Thread.run(Unknown Source)
]]>
      </failure>

          </testcase>
            <testcase name="Case3" time="3.065" classname="TestCase.LoginTest">
                <failure type="java.lang.AssertionError"
                  message="phone =&gt;Expected 【13111111112】 but found 【13111111111】"
              >
<![CDATA[java.lang.AssertionError: phone =>Expected 【13111111112】 but found 【13111111111】
  org.testng.Assert.fail(Assert.java:94)
  com.sales.webapi.handler.LoginApi_Handler.checkEquals(LoginApi_Handler.java:539)
  com.sales.webapi.handler.LoginApi_Handler.resultCheck(LoginApi_Handler.java:472)
  TestCase.LoginTest.Case3(LoginTest.java:32)
  sun.reflect.NativeMethodAccessorImpl.invoke0(Native Method)
  sun.reflect.NativeMethodAccessorImpl.invoke(Unknown Source)
  sun.reflect.DelegatingMethodAccessorImpl.invoke(Unknown Source)
  java.lang.reflect.Method.invoke(Unknown Source)
  org.testng.internal.MethodInvocationHelper.invokeMethod(MethodInvocationHelper.java:86)
  org.testng.internal.InvokeMethodRunnable.runOne(InvokeMethodRunnable.java:54)
  org.testng.internal.InvokeMethodRunnable.run(InvokeMethodRunnable.java:44)
  java.util.concurrent.Executors$RunnableAdapter.call(Unknown Source)
  java.util.concurrent.FutureTask.run(Unknown Source)
  java.util.concurrent.ThreadPoolExecutor.runWorker(Unknown Source)
  java.util.concurrent.ThreadPoolExecutor$Worker.run(Unknown Source)
  java.lang.Thread.run(Unknown Source)
]]>
      </failure>

          </testcase>
  
  
            <testcase name="Case1" time="3.387" classname="TestCase.LoginTest" />
      
</testsuite>
