<?xml version="1.0" encoding="UTF-8"?>
<!-- Generated by org.testng.reporters.JUnitReportReporter -->
<testsuite hostname="King" name="TestCases2.Login2" tests="7" failures="3" timestamp="30 Oct 2018 09:13:57 GMT" time="16.936" errors="0">
  <testcase name="Case6" time="2.022" classname="TestCases2.Login2"/>
  <testcase name="Case5" time="2.026" classname="TestCases2.Login2"/>
  <testcase name="Case3" time="2.203" classname="TestCases2.Login2">
    <failure type="java.lang.AssertionError" message="msg =&gt;Expected 【账号不能为空】 but found 【null】">
      <![CDATA[java.lang.AssertionError: msg =>Expected 【账号不能为空】 but found 【null】
	at org.testng.Assert.fail(Assert.java:94)
	at com.jmoney.luckeylink.handler.Login_Handler.checkEquals(Login_Handler.java:312)
	at com.jmoney.luckeylink.handler.Login_Handler.Login(Login_Handler.java:288)
	at TestCases2.Login2.Case3(Login2.java:28)
	at sun.reflect.NativeMethodAccessorImpl.invoke0(Native Method)
	at sun.reflect.NativeMethodAccessorImpl.invoke(NativeMethodAccessorImpl.java:62)
	at sun.reflect.DelegatingMethodAccessorImpl.invoke(DelegatingMethodAccessorImpl.java:43)
	at java.lang.reflect.Method.invoke(Method.java:498)
	at org.testng.internal.MethodInvocationHelper.invokeMethod(MethodInvocationHelper.java:86)
	at org.testng.internal.InvokeMethodRunnable.runOne(InvokeMethodRunnable.java:54)
	at org.testng.internal.InvokeMethodRunnable.run(InvokeMethodRunnable.java:44)
	at java.util.concurrent.Executors$RunnableAdapter.call(Executors.java:511)
	at java.util.concurrent.FutureTask.run(FutureTask.java:266)
	at java.util.concurrent.ThreadPoolExecutor.runWorker(ThreadPoolExecutor.java:1142)
	at java.util.concurrent.ThreadPoolExecutor$Worker.run(ThreadPoolExecutor.java:617)
	at java.lang.Thread.run(Thread.java:745)
]]>
    </failure>
  </testcase> <!-- Case3 -->
  <testcase name="Case4" time="2.178" classname="TestCases2.Login2">
    <failure type="java.lang.AssertionError" message="msg =&gt;Expected 【密码不能为空】 but found 【null】">
      <![CDATA[java.lang.AssertionError: msg =>Expected 【密码不能为空】 but found 【null】
	at org.testng.Assert.fail(Assert.java:94)
	at com.jmoney.luckeylink.handler.Login_Handler.checkEquals(Login_Handler.java:312)
	at com.jmoney.luckeylink.handler.Login_Handler.Login(Login_Handler.java:288)
	at TestCases2.Login2.Case4(Login2.java:33)
	at sun.reflect.NativeMethodAccessorImpl.invoke0(Native Method)
	at sun.reflect.NativeMethodAccessorImpl.invoke(NativeMethodAccessorImpl.java:62)
	at sun.reflect.DelegatingMethodAccessorImpl.invoke(DelegatingMethodAccessorImpl.java:43)
	at java.lang.reflect.Method.invoke(Method.java:498)
	at org.testng.internal.MethodInvocationHelper.invokeMethod(MethodInvocationHelper.java:86)
	at org.testng.internal.InvokeMethodRunnable.runOne(InvokeMethodRunnable.java:54)
	at org.testng.internal.InvokeMethodRunnable.run(InvokeMethodRunnable.java:44)
	at java.util.concurrent.Executors$RunnableAdapter.call(Executors.java:511)
	at java.util.concurrent.FutureTask.run(FutureTask.java:266)
	at java.util.concurrent.ThreadPoolExecutor.runWorker(ThreadPoolExecutor.java:1142)
	at java.util.concurrent.ThreadPoolExecutor$Worker.run(ThreadPoolExecutor.java:617)
	at java.lang.Thread.run(Thread.java:745)
]]>
    </failure>
  </testcase> <!-- Case4 -->
  <testcase name="Case2" time="2.157" classname="TestCases2.Login2">
    <failure type="java.lang.AssertionError" message="msg =&gt;Expected 【账号和密码不能为空】 but found 【null】">
      <![CDATA[java.lang.AssertionError: msg =>Expected 【账号和密码不能为空】 but found 【null】
	at org.testng.Assert.fail(Assert.java:94)
	at com.jmoney.luckeylink.handler.Login_Handler.checkEquals(Login_Handler.java:312)
	at com.jmoney.luckeylink.handler.Login_Handler.Login(Login_Handler.java:288)
	at TestCases2.Login2.Case2(Login2.java:23)
	at sun.reflect.NativeMethodAccessorImpl.invoke0(Native Method)
	at sun.reflect.NativeMethodAccessorImpl.invoke(NativeMethodAccessorImpl.java:62)
	at sun.reflect.DelegatingMethodAccessorImpl.invoke(DelegatingMethodAccessorImpl.java:43)
	at java.lang.reflect.Method.invoke(Method.java:498)
	at org.testng.internal.MethodInvocationHelper.invokeMethod(MethodInvocationHelper.java:86)
	at org.testng.internal.InvokeMethodRunnable.runOne(InvokeMethodRunnable.java:54)
	at org.testng.internal.InvokeMethodRunnable.run(InvokeMethodRunnable.java:44)
	at java.util.concurrent.Executors$RunnableAdapter.call(Executors.java:511)
	at java.util.concurrent.FutureTask.run(FutureTask.java:266)
	at java.util.concurrent.ThreadPoolExecutor.runWorker(ThreadPoolExecutor.java:1142)
	at java.util.concurrent.ThreadPoolExecutor$Worker.run(ThreadPoolExecutor.java:617)
	at java.lang.Thread.run(Thread.java:745)
]]>
    </failure>
  </testcase> <!-- Case2 -->
  <testcase name="Case7" time="2.070" classname="TestCases2.Login2"/>
  <testcase name="Case1" time="4.280" classname="TestCases2.Login2"/>
</testsuite> <!-- TestCases2.Login2 -->
